Workbook
Name b: Insumos!$XAO$1

Sheet Vituca Cakes
B3: N° | C3: Fecha | D3: Año | E3: Mes | F3: Cliente | G3: N° Artículo | H3: Categoría | I3: Detalle | J3: Unidades | K3: Costo Total | L3: Venta Total | M3: Ganancia | N3: Metodo de PAGO
B4: 1 | C4: 44100 | D4: =IF(C4="","",YEAR(C4)) -> 2020 | E4: =IF(C4="","",MONTH(C4)) -> 9 | F4: Agus Paramidani | G4: 2 | H4: macarrons | I4: sabores surtidos | J4: 5 | K4: 147 | L4: 350 | M4: =L4-K4 -> 203
B5: =B4+1 -> 2 | C5: 44101 | D5: =IF(C5="","",YEAR(C5)) -> 2020 | E5: =IF(C5="","",MONTH(C5)) -> 9 | F5: Lucas Capello | G5: 2 | H5: macarrons | I5: sabores surtidos | J5: 5 | K5: 147 | L5: 350 | M5: =L5-K5 -> 203
B6: =B5+1 -> 3 | C6: 44102 | D6: =IF(C6="","",YEAR(C6)) -> 2020 | E6: =IF(C6="","",MONTH(C6)) -> 9 | F6: Ornella D´estefano | H6: torta brownie | I6: frutos rojos tamaño 24cm | J6: 1 | K6: 409 | L6: 1000 | M6: =L6-K6 -> 591
B7: =B6+1 -> 4 | C7: 44102 | D7: =IF(C7="","",YEAR(C7)) -> 2020 | E7: =IF(C7="","",MONTH(C7)) -> 9 | F7: Leidymar | H7: desayuno | I7: 1 jugo baggio 1 mini budin limon1 mini budin marmolado, 4 cookies de chips de chocolate, 4 cookies en forma de flor, 1 porcion de brownie, 1 chocolatada, mantelito | J7: 1 | L7: 1200 | M7: =L7-K7 -> 1200
B8: =B7+1 -> 5 | C8: 44103 | D8: =IF(C8="","",YEAR(C8)) -> 2020 | E8: =IF(C8="","",MONTH(C8)) -> 9 | F8: Ornella D´estefano | H8: torta brownie | I8: frutos rojos tamaño 24cm | J8: 2 | K8: 818 | L8: 2200 | M8: =L8-K8 -> 1382
B9: =B8+1 -> 6 | C9: 44104 | D9: =IF(C9="","",YEAR(C9)) -> 2020 | E9: =IF(C9="","",MONTH(C9)) -> 9 | F9: Maxi Cardoso | H9: macarrons | I9: 4 chocolate blanco 2 limon 2 frutilla y 2 chocolate | J9: 10 | K9: 294 | L9: 600 | M9: =L9-K9 -> 306
B10: =B9+1 -> 7 | C10: 44107 | D10: =IF(C10="","",YEAR(C10)) -> 2020 | E10: =IF(C10="","",MONTH(C10)) -> 10 | F10: Carolina Marsaudon | H10: torta brownie 24 cm | I10: ddl, crema, frutillas y chocolates | J10: 1 | K10: 450 | L10: 1100 | M10: =L10-K10 -> 650
B11: =B10+1 -> 8 | C11: 44107 | D11: =IF(C11="","",YEAR(C11)) -> 2020 | E11: =IF(C11="","",MONTH(C11)) -> 10 | F11: Gaby Morales | H11: Lemon Pie | I11: 20 cm | J11: 1 | K11: 300 | L11: 850 | M11: =L11-K11 -> 550
B12: =B11+1 -> 9 | C12: 44107 | D12: =IF(C12="","",YEAR(C12)) -> 2020 | E12: =IF(C12="","",MONTH(C12)) -> 10 | F12: Gaby Morales | H12: torta brownie | I12: Frutos rojos tamaño 20cm | J12: 1 | K12: 288 | L12: 950 | M12: =L12-K12 -> 662
B13: =B12+1 -> 10 | C13: 44107 | D13: =IF(C13="","",YEAR(C13)) -> 2020 | E13: =IF(C13="","",MONTH(C13)) -> 10 | F13: Agus Perez Romero | H13: Chipa | I13: 1/4 GANADOR! | J13: 1 | K13: 109 | L13: 0 | M13: =L13-K13 -> -109
B14: =B13+1 -> 11 | C14: 44107 | D14: =IF(C14="","",YEAR(C14)) -> 2020 | E14: =IF(C14="","",MONTH(C14)) -> 10 | F14: Priscila Pacifisco | H14: Chipa | I14: 0.5 | J14: 1 | K14: 218 | L14: 360 | M14: =L14-K14 -> 142
B15: =B14+1 -> 12 | C15: 44107 | D15: =IF(C15="","",YEAR(C15)) -> 2020 | E15: =IF(C15="","",MONTH(C15)) -> 10 | F15: Caro Ponti | H15: Pan Trenzado | I15: con semillas | J15: 2 | K15: 72 | L15: 160 | M15: =L15-K15 -> 88
B16: =B15+1 -> 13 | C16: 44107 | D16: =IF(C16="","",YEAR(C16)) -> 2020 | E16: =IF(C16="","",MONTH(C16)) -> 10 | F16: Caro Ponti | H16: Chipa | I16: 0.25 | J16: 1 | K16: 109 | L16: 180 | M16: =L16-K16 -> 71
B17: =B16+1 -> 14 | C17: 44107 | D17: =IF(C17="","",YEAR(C17)) -> 2020 | E17: =IF(C17="","",MONTH(C17)) -> 10 | F17: Estefi Garbarino | H17: Chipa | I17: 0.25 | J17: 1 | K17: 109 | L17: 180 | M17: =L17-K17 -> 71 | N17: PAGO, TRANSFERENCIA
B18: =B17+1 -> 15 | C18: 44108 | D18: =IF(C18="","",YEAR(C18)) -> 2020 | E18: =IF(C18="","",MONTH(C18)) -> 10 | F18: Flor Daboum | H18: macarrons | I18: surtidos blancos y rosas | J18: 5 | K18: 147 | L18: 150 | M18: =L18-K18 -> 3
B19: =B18+1 -> 16 | C19: 44108 | D19: =IF(C19="","",YEAR(C19)) -> 2020 | E19: =IF(C19="","",MONTH(C19)) -> 10 | F19: Flor Vitola | H19: desayuno PLIM PLIM | I19: Baggio, globo, 2 muffins buttercream, 2 cookies glase, 4 cookies chupetin | J19: 1 | K19: 365 | L19: 850 | M19: =L19-K19 -> 485
B20: =B19+1 -> 17 | C20: 44108 | D20: =IF(C20="","",YEAR(C20)) -> 2020 | E20: =IF(C20="","",MONTH(C20)) -> 10 | F20: Flor Vitola | H20: Desayuno FORTNITE | I20: igual que plim plim pero de fortnite | J20: 1 | K20: 365 | L20: 850 | M20: =L20-K20 -> 485
B21: =B20+1 -> 18 | C21: 44108 | D21: =IF(C21="","",YEAR(C21)) -> 2020 | E21: =IF(C21="","",MONTH(C21)) -> 10 | F21: Vicky Minoli | H21: macarrons + tarta manzana | I21: M 3 Limon y 3 Frutilla T: 24 CM | J21: 6 + 1 | K21: 594 | L21: 1200 | M21: =L21-K21 -> 606
B22: =B21+1 -> 19 | C22: 44109 | D22: =IF(C22="","",YEAR(C22)) -> 2020 | E22: =IF(C22="","",MONTH(C22)) -> 10 | F22: Daniela Ares | H22: torta bizcochuelo 50 | I22: dulce de leche-crema y merengue / rosa y dorado | J22: 1 | L22: 3400 | M22: =L22-K22 -> 3400
B23: =B22+1 -> 20 | C23: 44111 | D23: =IF(C23="","",YEAR(C23)) -> 2020 | E23: =IF(C23="","",MONTH(C23)) -> 10 | F23: Lorena Cossovich | H23: torta ferrero rocher + macarrons | I23: 10 macarrons Surtidos, torta 20 cm | J23: 10+ 1 | K23: 1069 | L23: 2350 | M23: =L23-K23 -> 1281
B24: =B23+1 -> 21 | C24: 44113 | D24: =IF(C24="","",YEAR(C24)) -> 2020 | E24: =IF(C24="","",MONTH(C24)) -> 10 | F24: Roxana Solis | H24: Torta Piñata | I24: tematica: DINOSAURIO / ELLOS ME DAN LAS GOLOSINAS | J24: 1 | K24: 322 | L24: 1200 | M24: =L24-K24 -> 878
B25: 22 | C25: 44121 | D25: =IF(C25="","",YEAR(C25)) -> 2020 | E25: =IF(C25="","",MONTH(C25)) -> 10 | F25: Jaqueline | H25: tarta de frutillas y tarta de durazno | I25: 24 cm con pastelera, retira! | J25: 2 | K25: 705 | L25: 1630 | M25: =L25-K25 -> 925 | N25: PAGO SEÑA
B26: 23 | C26: 44122 | D26: =IF(C26="","",YEAR(C26)) -> 2020 | E26: =IF(C26="","",MONTH(C26)) -> 10 | F26: Roxana Solis | H26: Torta Piñata | I26: tematica: TIC TOC / ELLOS ME DAN LAS GOLOSINAS | J26: 1 | K26: 322 | L26: 1200 | M26: =L26-K26 -> 878 | N26: PAGO, TRANSFERENCIA
B27: =B26+1 -> 24 | C27: 44122 | D27: =IF(C27="","",YEAR(C27)) -> 2020 | E27: =IF(C27="","",MONTH(C27)) -> 10 | F27: ezequiel | H27: DIA DE LA MADRE | I27: OPCION 1 | J27: 1 | K27: 787 | L27: 1400 | M27: =L27-K27 -> 613 | N27: PAGO, MERCADO PAGO
B28: =B27+1 -> 25 | C28: 44122 | D28: =IF(C28="","",YEAR(C28)) -> 2020 | E28: =IF(C28="","",MONTH(C28)) -> 10 | F28: Miriam | H28: DIA DE LA MADRE | I28: OPCION 1 + 6 MARPLATENSE + 2 CUCHARAS | J28: 1 | K28: 900 | L28: 1350 | M28: =L28-K28 -> 450 | N28: EFECTIVO
B29: =B28+1 -> 26 | C29: 44122 | D29: =IF(C29="","",YEAR(C29)) -> 2020 | E29: =IF(C29="","",MONTH(C29)) -> 10 | F29: Meco | H29: DIA DE LA MADRE | I29: OPCION 2 | J29: 1 | K29: 787 | L29: 1000 | M29: =L29-K29 -> 213
B30: =B29+1 -> 27 | C30: 44122 | D30: =IF(C30="","",YEAR(C30)) -> 2020 | E30: =IF(C30="","",MONTH(C30)) -> 10 | F30: Cora | H30: DIA DE LA MADRE | I30: OPCION 1 | J30: 2 | K30: 787 | L30: 1600 | M30: =L30-K30 -> 813
B31: =B30+1 -> 28 | C31: 44122 | D31: =IF(C31="","",YEAR(C31)) -> 2020 | E31: =IF(C31="","",MONTH(C31)) -> 10 | F31: Adrian Lopresto | H31: DIA DE LA MADRE | I31: OPCION 2 | J31: 1 | K31: 787 | L31: 1600 | M31: =L31-K31 -> 813 | N31: PAGO, EFECTIVO
B32: =B31+1 -> 29 | C32: 44122 | D32: =IF(C32="","",YEAR(C32)) -> 2020 | E32: =IF(C32="","",MONTH(C32)) -> 10 | F32: Caterina | H32: DIA DE LA MADRE | I32: OPCION 1 | J32: 1 | K32: 787 | L32: 1200 | M32: =L32-K32 -> 413 | N32: PAGO, MERCADO PAGO
B33: =B32+1 -> 30 | C33: 44122 | D33: =IF(C33="","",YEAR(C33)) -> 2020 | E33: =IF(C33="","",MONTH(C33)) -> 10 | F33: Erica | H33: DIA DE LA MADRE | I33: OPCION 1 | J33: 1 | K33: 787 | L33: 1200 | M33: =L33-K33 -> 413 | N33: EFECTIVO
B34: =B33+1 -> 31 | C34: 44122 | D34: =IF(C34="","",YEAR(C34)) -> 2020 | E34: =IF(C34="","",MONTH(C34)) -> 10 | F34: Laura Parroquia | H34: DIA DE LA MADRE | I34: OPCION 2 | J34: 1 | K34: 787 | L34: 1600 | M34: =L34-K34 -> 813 | N34: EFECTIVO
B35: =B34+1 -> 32 | C35: 44122 | D35: =IF(C35="","",YEAR(C35)) -> 2020 | E35: =IF(C35="","",MONTH(C35)) -> 10 | F35: Julian Petruzzelli | H35: DIA DE LA MADRE | I35: OPCION 2 | J35: 1 | K35: 787 | L35: 1600 | M35: =L35-K35 -> 813
B36: =B35+1 -> 33 | C36: 44122 | D36: =IF(C36="","",YEAR(C36)) -> 2020 | E36: =IF(C36="","",MONTH(C36)) -> 10 | F36: Flor Vitola | H36: DIA DE LA MADRE | I36: OPCION 2 | J36: 1 | K36: 787 | L36: 1600 | M36: =L36-K36 -> 813 | N36: PAGO, TRANSFERENCIA
B37: =B36+1 -> 34 | C37: 44122 | D37: =IF(C37="","",YEAR(C37)) -> 2020 | E37: =IF(C37="","",MONTH(C37)) -> 10 | F37: Nicole Avila | H37: DIA DE LA MADRE | I37: OPCION 1 | J37: 1 | K37: 787 | L37: 1200 | M37: =L37-K37 -> 413 | N37: PAGO, MERCADO PAGO
B38: =B37+1 -> 35 | C38: 44122 | D38: =IF(C38="","",YEAR(C38)) -> 2020 | E38: =IF(C38="","",MONTH(C38)) -> 10 | F38: Nicolas Ferros | H38: DIA DE LA MADRE | I38: OPCION 2 | J38: 1 | K38: 787 | L38: 1700 | M38: =L38-K38 -> 913 | N38: PAGO, MERCADO PAGO
B39: =B38+1 -> 36 | C39: 44124 | D39: =IF(C39="","",YEAR(C39)) -> 2020 | E39: =IF(C39="","",MONTH(C39)) -> 10 | F39: MARISEL | H39: DESAYUNO | I39: 2 macarrons choco b y choco, 4 maicena 1 brownie y 4 cookies feliz cumple | J39: 1 | K39: 787 | L39: 1100 | M39: =L39-K39 -> 313 | N39: PAGO, TRANSFERENCIA
B40: =B39+1 -> 37 | C40: 44125 | D40: =IF(C40="","",YEAR(C40)) -> 2020 | E40: =IF(C40="","",MONTH(C40)) -> 10 | F40: MARISEL | H40: DESAYUNO | I40: 2 macarrons choco b y choco, 4 maicena 1 brownie y 4 cookies feliz cumple y globo corazon rosa | J40: 1 | K40: 500 | L40: 1200 | M40: =L40-K40 -> 700 | N40: PAGO, TRANSFERENCIA
B41: =B40+1 -> 38 | C41: 44127 | D41: =IF(C41="","",YEAR(C41)) -> 2020 | E41: =IF(C41="","",MONTH(C41)) -> 10 | F41: NORBERTO | H41: DESAYUNOS | I41: 2 Cookies, 2 budin de chocolate, baggio, taza. Bandeja | J41: 108 | K41: =329*108 -> 35532 | L41: 51840 | M41: =L41-K41 -> 16308 | N41: pago 35.000
B42: 39 | C42: 44135 | D42: =IF(C42="","",YEAR(C42)) -> 2020 | E42: =IF(C42="","",MONTH(C42)) -> 10 | F42: Silvia Lois | H42: HALOWEEN | I42: 12 COOKIES 12 MACARRONS (CHO. CHO B) 6 FANTASMITAS | J42: 1 | K42: 352 | L42: 1870 | M42: =L42-K42 -> 1518 | N42: EFECTIVO
...

Sheet Sheet1
B2: Artículo | C2: Porciones | D2: Precio | F2: Costo | G2: Rentabilidad | H2: Rentabilidad %
B3: Alfajores de Nuez x12 | C3: 12 | D3: 9000 | F3: =VLOOKUP(B3,'Costo x Articulo'!$C$3:$G$153,5,0) -> 3643.1667 | G3: =D3-F3 -> 5356.8333 | H3: =G3/F3 -> 1.4703783
B4: Budín de frutos secos | C4: 10 | D4: 14000 | F4: =VLOOKUP(B4,'Costo x Articulo'!$C$3:$G$153,5,0) -> 6604.7333 | G4: =D4-F4 -> 7395.2667 | H4: =G4/F4 -> 1.1196919
B5: Budín de limón | C5: 10 | D5: 12000 | F5: =VLOOKUP(B5,'Costo x Articulo'!$C$3:$G$153,5,0) -> 5558.0667 | G5: =D5-F5 -> 6441.9333 | H5: =G5/F5 -> 1.1590241
B6: Carrot Cake 22cm | C6: 8 | D6: 14500 | F6: =VLOOKUP(B6,'Costo x Articulo'!$C$3:$G$153,5,0) -> 5555.9524 | G6: =D6-F6 -> 8944.0476 | H6: =G6/F6 -> 1.6098136
B7: Carrot Cake Mini | C7: 1 | D7: 2900 | F7: =F6/6 -> 925.99206 | G7: =D7-F7 -> 1974.0079 | H7: =G7/F7 -> 2.1317763
B8: Cheescake 22cm | C8: 8 | D8: 26000 | F8: =VLOOKUP(B8,'Costo x Articulo'!$C$3:$G$153,5,0) -> 15249.932 | G8: =D8-F8 -> 10750.068 | H8: =G8/F8 -> 0.70492565
B9: Cheescake Mini | C9: 1 | D9: 3500 | F9: =F8/6 -> 2541.6553 | G9: =D9-F9 -> 958.34469 | H9: =G9/F9 -> 0.37705534
B10: Chocotorta clásica redonda 22cm | C10: 8 | D10: 25000 | F10: =VLOOKUP(B10,'Costo x Articulo'!$C$3:$G$153,5,0) -> 16903.571 | G10: =D10-F10 -> 8096.4286 | H10: =G10/F10 -> 0.47897739
B11: Chocotorta clásica cuadrada Mini | C11: 1 | D11: 3500 | F11: =F10/6 -> 2817.2619 | G11: =D11-F11 -> 682.7381 | H11: =G11/F11 -> 0.24234101
B12: Cookies Chips Chocolatesx15 | C12: 15 | D12: 6000 | F12: =VLOOKUP(B12,'Costo x Articulo'!$C$3:$G$153,5,0) -> 2411.1267 | G12: =D12-F12 -> 3588.8733 | H12: =G12/F12 -> 1.4884632
B13: Doble Oreo 22cm | C13: 8 | D13: 24000 | F13: =VLOOKUP(B13,'Costo x Articulo'!$C$3:$G$153,5,0) -> 17915 | G13: =D13-F13 -> 6085 | H13: =G13/F13 -> 0.3396595
B14: Doble Oreo Mini | C14: 1 | D14: 3500 | F14: =F13/6 -> 2985.8333 | G14: =D14-F14 -> 514.16667 | H14: =G14/F14 -> 0.17220207
B15: Lemon pie 24cm | C15: 8 | D15: 21000 | F15: =VLOOKUP(B15,'Costo x Articulo'!$C$3:$G$153,5,0) -> 9123.5333 | G15: =D15-F15 -> 11876.467 | H15: =G15/F15 -> 1.3017398
B16: Lemon pie Mini | C16: 1 | D16: 2700 | F16: =F15/6 -> 1520.5889 | G16: =D16-F16 -> 1179.4111 | H16: =G16/F16 -> 0.77562786
B17: Macarrons x 12 unidades | C17: 12 | D17: 9000 | F17: =VLOOKUP(B17,'Costo x Articulo'!$C$3:$G$153,5,0) -> 3391.1333 | G17: =D17-F17 -> 5608.8667 | H17: =G17/F17 -> 1.65398
B18: Tarta de Manzana 22cm | C18: 8 | D18: 16000 | F18: =VLOOKUP(B18,'Costo x Articulo'!$C$3:$G$153,5,0) -> 6706.1167 | G18: =D18-F18 -> 9293.8833 | H18: =G18/F18 -> 1.3858815
B19: Tarta de Manzana Mini | C19: 1 | D19: 2900 | F19: =F18/6 -> 1117.6861 | G19: =D19-F19 -> 1782.3139 | H19: =G19/F19 -> 1.5946462
B20: Torta brownie 20x20cm | C20: 8 | D20: 22000 | F20: =VLOOKUP(B20,'Costo x Articulo'!$C$3:$G$153,5,0) -> 10233.328 | G20: =D20-F20 -> 11766.672 | H20: =G20/F20 -> 1.1498383
B21: Torta brownie Mini | C21: 1 | D21: 3000 | F21: =F20/6 -> 1705.5546 | G21: =D21-F21 -> 1294.4454 | H21: =G21/F21 -> 0.75895861

Sheet Margen
B2: Mes | C2: Insumos | D2: Ventas | E2: Margen
B3: 45566 | C3: =59000+90700+30000+15000+4400+36150+4300+9900-8000+59310 -> 300760 | D3: =17800+36000+81500+65400+31600+15000+30000+40000+51000+90000+20000+42000+38500+17500 -> 576300 | E3: =IFERROR(D3/C3-1,0) -> 0.91614576
B4: 45597 | C4: =61000+21050+2000+23000+33100 -> 140150 | E4: =IFERROR(D4/C4-1,0) -> -1
B5: 45627 | C5: 85500 | E5: =IFERROR(D5/C5-1,0) -> -1

Sheet Insumos
B3: Insumo | C3: Unidad | D3: Cantidad | E3: Costo | F3: CU | G3: Fecha
B4: 3
B5: Aceite | C5: Cm3 | D5: 3500 | E5: 4500 | F5: =E5/D5 -> 1.2857143 | G5: 45320
B6: albaca | C6: Unidad | D6: 1 | E6: 1800 | F6: =E6/D6 -> 1800
B7: Almedras | C7: Grs | D7: 100 | E7: 1700 | F7: =E7/D7 -> 17 | G7: 45276
B8: aquafaba | C8: Cm3 | D8: 148 | E8: 819 | F8: =E8/D8 -> 5.5337838 | G8: 45320
B9: atun | C9: Unidad | D9: 1 | E9: 2500 | F9: =E9/D9 -> 2500
B10: Azúcar | C10: Grs | D10: 10000 | E10: 14000 | F10: =E10/D10 -> 1.4 | G10: 46145
B11: Azúcar granulada | C11: Grs | D11: 1000 | E11: 15000 | F11: =E11/D11 -> 15 | G11: 45377
B12: Azúcar impalpable | C12: Grs | D12: 10000 | E12: 15000 | F12: =E12/D12 -> 1.5 | G12: 46145
B13: Azucar Negra | C13: Grs | D13: 1000 | E13: 850 | F13: =E13/D13 -> 0.85 | G13: 45082
B14: Baggio | C14: Unidad | D14: 1 | E14: 700 | F14: =E14/D14 -> 700 | G14: 45635
B15: Bandeja cuadrada 10x10 | C15: Unidad | D15: 1 | E15: 400 | F15: =E15/D15 -> 400 | G15: 45565
B16: bandeja mandera logo 25 cm | C16: Unidad | D16: 1 | E16: 1300 | F16: =E16/D16 -> 1300 | G16: 46145
B17: Bandeja N°6 30x25 | C17: Unidad | D17: 100 | E17: 500 | F17: =E17/D17 -> 5
B18: Bandeja redonda 14 cm | C18: Unidad | D18: 1 | E18: 10.2 | F18: =E18/D18 -> 10.2
B19: Bandeja redonda 24cm rigida | C19: Unidad | D19: 1 | E19: 1300 | F19: =E19/D19 -> 1300 | G19: 45492
B20: Bandeja redonda 28cm logo | C20: Unidad | D20: 1 | E20: 1610 | F20: =E20/D20 -> 1610 | G20: 46145
B21: Bandeja Rígida y logo 40x30 | C21: Unidad | D21: 1 | E21: 2250 | F21: =E21/D21 -> 2250 | G21: 45877
B22: Batata | C22: Grs | D22: 500 | E22: 2300 | F22: =E22/D22 -> 4.6 | G22: 45635
B23: Bicarbonato de sodio | C23: Grs | D23: 25 | E23: 416 | F23: =E23/D23 -> 16.64 | G23: 45635
B24: Bloda n°12 | C24: Unidad | D24: 100 | E24: 396 | F24: =E24/D24 -> 3.96 | G24: 45082
B25: Blonda | C25: Unidad | D25: 100 | E25: 625 | F25: =E25/D25 -> 6.25 | G25: 45082
B26: Bolsa 40x30 | C26: Unidad | D26: 100 | E26: 794 | F26: =E26/D26 -> 7.94 | G26: 45082
B27: bolsa condimento bondiola | C27: Unidad | D27: 1 | E27: 1800 | F27: =E27/D27 -> 1800
B28: Bolsa de madera | C28: Unidad | D28: 1 | E28: 34 | F28: =E28/D28 -> 34 | G28: 45082
B29: Bolsa de papel Argentina | C29: Unidad | D29: 10 | E29: 1000 | F29: =E29/D29 -> 100 | G29: 45017
B30: Bolsa de polipropileno x 100 un. | C30: Unidad | D30: 100 | E30: 1100 | F30: =E30/D30 -> 11 | G30: 45276
B31: Bolsitas 12x15 | C31: Unidad | D31: 200 | E31: 202 | F31: =E31/D31 -> 1.01 | G31: 45082
B32: Bombom corazon | C32: Unidad | D32: 1 | E32: 50 | F32: =E32/D32 -> 50
B33: bondiola 1kg | C33: Grs | D33: 1000 | E33: 6200 | F33: =E33/D33 -> 6.2
B34: Botella vidrio 250cc | C34: Unidad | D34: 30 | E34: 2515 | F34: =E34/D34 -> 83.833333
B35: brochette | C35: Unidad | D35: 100 | E35: 1750 | F35: =E35/D35 -> 17.5
B36: Budinera papel x500grms | C36: Unidad | D36: 1 | E36: 40 | F36: =E36/D36 -> 40 | G36: 45082
B37: Cacao | C37: Grs | D37: 180 | E37: 6500 | F37: =E37/D37 -> 36.111111 | G37: 46145
B38: Cacao alcalino | C38: Grs | D38: 1000 | E38: 36000 | F38: =E38/D38 -> 36 | G38: 46145
B39: Café en saquito | C39: Unidad | D39: 20 | E39: 441 | F39: =E39/D39 -> 22.05 | G39: 45082
B40: Café Instantaneo | C40: Grs | D40: 170 | E40: 798 | F40: =E40/D40 -> 4.6941176 | G40: 45082
B41: Caja maletin kraf 25x25x15 | C41: Unidad | D41: 1 | E41: 975 | F41: =E41/D41 -> 975 | G41: 46145
B42: Caja 32x25x10 | C42: Unidad | D42: 1 | E42: 358 | F42: =E42/D42 -> 358 | G42: 45082
...

Sheet Recetas
D1: 2 | F1: =D1+1 -> 3 | G1: =F1+1 -> 4
B2: Nro. | C2: Receta | D2: Ingrediente | E2: Unidad | F2: Cantidad | G2: Precio por 1 | H2: Total
B3: 1 | C3: Budín de limón | D3: Manteca | E3: =IFERROR(VLOOKUP($D3,Insumos!$B:$U,D$1,0),"") -> Grs | F3: 200 | G3: =IFERROR(VLOOKUP($D3,Insumos!$B:$U,G$1,0)/VLOOKUP($D3,Insumos!$B:$U,F$1,0),"") -> 11 | H3: =IFERROR(F3*G3,"") -> 2200
B4: =IF($D4="","",B3) -> 1 | C4: =IF($D4="","",C3) -> Budín de limón | D4: Azúcar | E4: =IFERROR(VLOOKUP($D4,Insumos!$B:$U,D$1,0),"") -> Grs | F4: 200 | G4: =IFERROR(VLOOKUP($D4,Insumos!$B:$U,G$1,0)/VLOOKUP($D4,Insumos!$B:$U,F$1,0),"") -> 1.4 | H4: =IFERROR(F4*G4,"") -> 280
B5: =IF($D5="","",B4) -> 1 | C5: =IF($D5="","",C4) -> Budín de limón | D5: Huevo | E5: =IFERROR(VLOOKUP($D5,Insumos!$B:$U,D$1,0),"") -> Unidad | F5: 4 | G5: =IFERROR(VLOOKUP($D5,Insumos!$B:$U,G$1,0)/VLOOKUP($D5,Insumos!$B:$U,F$1,0),"") -> 166.66667 | H5: =IFERROR(F5*G5,"") -> 666.66667
B6: =IF($D6="","",B5) -> 1 | C6: =IF($D6="","",C5) -> Budín de limón | D6: Harina 0000 | E6: =IFERROR(VLOOKUP($D6,Insumos!$B:$U,D$1,0),"") -> Grs | F6: 270 | G6: =IFERROR(VLOOKUP($D6,Insumos!$B:$U,G$1,0)/VLOOKUP($D6,Insumos!$B:$U,F$1,0),"") -> 0.82 | H6: =IFERROR(F6*G6,"") -> 221.4
B7: =IF($D7="","",B6) -> 1 | C7: =IF($D7="","",C6) -> Budín de limón | D7: Polvo de hornear | E7: =IFERROR(VLOOKUP($D7,Insumos!$B:$U,D$1,0),"") -> Grs | F7: 10 | G7: =IFERROR(VLOOKUP($D7,Insumos!$B:$U,G$1,0)/VLOOKUP($D7,Insumos!$B:$U,F$1,0),"") -> 8 | H7: =IFERROR(F7*G7,"") -> 80
B8: =IF($D8="","",B6) -> 1 | C8: =IF($D8="","",C6) -> Budín de limón | D8: Limón | E8: =IFERROR(VLOOKUP($D8,Insumos!$B:$U,D$1,0),"") -> Unidad | F8: 2 | G8: =IFERROR(VLOOKUP($D8,Insumos!$B:$U,G$1,0)/VLOOKUP($D8,Insumos!$B:$U,F$1,0),"") -> 180 | H8: =IFERROR(F8*G8,"") -> 360
B9: =IF($D9="","",B7) -> 1 | C9: =IF($D9="","",C7) -> Budín de limón | D9: Disco dorado 24 | E9: =IFERROR(VLOOKUP($D9,Insumos!$B:$U,D$1,0),"") -> Unidad | F9: 1 | G9: =IFERROR(VLOOKUP($D9,Insumos!$B:$U,G$1,0)/VLOOKUP($D9,Insumos!$B:$U,F$1,0),"") -> 400 | H9: =IFERROR(F9*G9,"") -> 400
B10: =IF($D10="","",B8) -> 1 | C10: =IF($D10="","",C8) -> Budín de limón | D10: Caja maletin kraf 25x25x15 | E10: =IFERROR(VLOOKUP($D10,Insumos!$B:$U,D$1,0),"") -> Unidad | F10: 1 | G10: =IFERROR(VLOOKUP($D10,Insumos!$B:$U,G$1,0)/VLOOKUP($D10,Insumos!$B:$U,F$1,0),"") -> 975 | H10: =IFERROR(F10*G10,"") -> 975
B11: =IF($D11="","",B10) -> 1 | C11: =IF($D11="","",C10) -> Budín de limón | D11: Azúcar impalpable | E11: =IFERROR(VLOOKUP($D11,Insumos!$B:$U,D$1,0),"") -> Grs | F11: 250 | G11: =IFERROR(VLOOKUP($D11,Insumos!$B:$U,G$1,0)/VLOOKUP($D11,Insumos!$B:$U,F$1,0),"") -> 1.5 | H11: =IFERROR(F11*G11,"") -> 375
B12: 2 | C12: Macarrons x 12 unidades | D12: Azúcar | E12: =IFERROR(VLOOKUP($D12,Insumos!$B:$U,D$1,0),"") -> Grs | F12: =130/30*12 -> 52 | G12: =IFERROR(VLOOKUP($D12,Insumos!$B:$U,G$1,0)/VLOOKUP($D12,Insumos!$B:$U,F$1,0),"") -> 1.4 | H12: =IFERROR(F12*G12,"") -> 72.8
B13: =IF($D13="","",B12) -> 2 | C13: =IF($D13="","",C12) -> Macarrons x 12 unidades | D13: Harina de almendras | E13: =IFERROR(VLOOKUP($D13,Insumos!$B:$U,D$1,0),"") -> Grs | F13: =65/30*12 -> 26 | G13: =IFERROR(VLOOKUP($D13,Insumos!$B:$U,G$1,0)/VLOOKUP($D13,Insumos!$B:$U,F$1,0),"") -> 32 | H13: =IFERROR(F13*G13,"") -> 832
B14: =IF($D14="","",B13) -> 2 | C14: =IF($D14="","",C13) -> Macarrons x 12 unidades | D14: Huevo | E14: =IFERROR(VLOOKUP($D14,Insumos!$B:$U,D$1,0),"") -> Unidad | F14: =2/30*12 -> 0.8 | G14: =IFERROR(VLOOKUP($D14,Insumos!$B:$U,G$1,0)/VLOOKUP($D14,Insumos!$B:$U,F$1,0),"") -> 166.66667 | H14: =IFERROR(F14*G14,"") -> 133.33333
B15: =IF($D15="","",B14) -> 2 | C15: =IF($D15="","",C14) -> Macarrons x 12 unidades | D15: Azúcar impalpable | E15: =IFERROR(VLOOKUP($D15,Insumos!$B:$U,D$1,0),"") -> Grs | F15: =65/30*12 -> 26 | G15: =IFERROR(VLOOKUP($D15,Insumos!$B:$U,G$1,0)/VLOOKUP($D15,Insumos!$B:$U,F$1,0),"") -> 1.5 | H15: =IFERROR(F15*G15,"") -> 39
B16: =IF($D16="","",B15) -> 2 | C16: =IF($D16="","",C15) -> Macarrons x 12 unidades | D16: Colorante | E16: =IFERROR(VLOOKUP($D16,Insumos!$B:$U,D$1,0),"") -> Grs | F16: =3/30*12 -> 1.2 | G16: =IFERROR(VLOOKUP($D16,Insumos!$B:$U,G$1,0)/VLOOKUP($D16,Insumos!$B:$U,F$1,0),"") -> 120 | H16: =IFERROR(F16*G16,"") -> 144
B17: =IF($D17="","",B16) -> 2 | C17: =IF($D17="","",C16) -> Macarrons x 12 unidades | D17: Saborizante | E17: =IFERROR(VLOOKUP($D17,Insumos!$B:$U,D$1,0),"") -> Grs | F17: =10/30*12 -> 4 | G17: =IFERROR(VLOOKUP($D17,Insumos!$B:$U,G$1,0)/VLOOKUP($D17,Insumos!$B:$U,F$1,0),"") -> 48 | H17: =IFERROR(F17*G17,"") -> 192
B18: =IF($D18="","",B17) -> 2 | C18: =IF($D18="","",C17) -> Macarrons x 12 unidades | D18: Crema de leche | E18: =IFERROR(VLOOKUP($D18,Insumos!$B:$U,D$1,0),"") -> Grs | F18: =100/30*12 -> 40 | G18: =IFERROR(VLOOKUP($D18,Insumos!$B:$U,G$1,0)/VLOOKUP($D18,Insumos!$B:$U,F$1,0),"") -> 9.2 | H18: =IFERROR(F18*G18,"") -> 368
B19: =IF($D19="","",B18) -> 2 | C19: =IF($D19="","",C18) -> Macarrons x 12 unidades | D19: Chocolate | E19: =IFERROR(VLOOKUP($D19,Insumos!$B:$U,D$1,0),"") -> Grs | F19: 40 | G19: =IFERROR(VLOOKUP($D19,Insumos!$B:$U,G$1,0)/VLOOKUP($D19,Insumos!$B:$U,F$1,0),"") -> 10 | H19: =IFERROR(F19*G19,"") -> 400
B20: =IF($D20="","",B19) -> 2 | C20: =IF($D20="","",C19) -> Macarrons x 12 unidades | D20: Mangas descartables N°4 | E20: =IFERROR(VLOOKUP($D20,Insumos!$B:$U,D$1,0),"") -> Unidad | F20: 2 | G20: =IFERROR(VLOOKUP($D20,Insumos!$B:$U,G$1,0)/VLOOKUP($D20,Insumos!$B:$U,F$1,0),"") -> 400 | H20: =IFERROR(F20*G20,"") -> 800
B21: =IF($D21="","",B20) -> 2 | C21: =IF($D21="","",C20) -> Macarrons x 12 unidades | D21: Caja macarrons x12 | E21: =IFERROR(VLOOKUP($D21,Insumos!$B:$U,D$1,0),"") -> Unidad | F21: 1 | G21: =IFERROR(VLOOKUP($D21,Insumos!$B:$U,G$1,0)/VLOOKUP($D21,Insumos!$B:$U,F$1,0),"") -> 410 | H21: =IFERROR(F21*G21,"") -> 410
B22: 3 | C22: Lemon pie 24cm | D22: Manteca | E22: =IFERROR(VLOOKUP($D22,Insumos!$B:$U,D$1,0),"") -> Grs | F22: =180+150 -> 330 | G22: =IFERROR(VLOOKUP($D22,Insumos!$B:$U,G$1,0)/VLOOKUP($D22,Insumos!$B:$U,F$1,0),"") -> 11 | H22: =IFERROR(F22*G22,"") -> 3630
B23: =IF($D23="","",B22) -> 3 | C23: =IF($D23="","",C22) -> Lemon pie 24cm | D23: Harina 0000 | E23: =IFERROR(VLOOKUP($D23,Insumos!$B:$U,D$1,0),"") -> Grs | F23: 300 | G23: =IFERROR(VLOOKUP($D23,Insumos!$B:$U,G$1,0)/VLOOKUP($D23,Insumos!$B:$U,F$1,0),"") -> 0.82 | H23: =IFERROR(F23*G23,"") -> 246
B24: =IF($D24="","",B23) -> 3 | C24: =IF($D24="","",C23) -> Lemon pie 24cm | D24: Azúcar impalpable | E24: =IFERROR(VLOOKUP($D24,Insumos!$B:$U,D$1,0),"") -> Grs | F24: 120 | G24: =IFERROR(VLOOKUP($D24,Insumos!$B:$U,G$1,0)/VLOOKUP($D24,Insumos!$B:$U,F$1,0),"") -> 1.5 | H24: =IFERROR(F24*G24,"") -> 180
B25: =IF($D25="","",B24) -> 3 | C25: =IF($D25="","",C24) -> Lemon pie 24cm | D25: Huevo | E25: =IFERROR(VLOOKUP($D25,Insumos!$B:$U,D$1,0),"") -> Unidad | F25: =2+4+2 -> 8 | G25: =IFERROR(VLOOKUP($D25,Insumos!$B:$U,G$1,0)/VLOOKUP($D25,Insumos!$B:$U,F$1,0),"") -> 166.66667 | H25: =IFERROR(F25*G25,"") -> 1333.3333
B26: =IF($D26="","",B25) -> 3 | C26: =IF($D26="","",C25) -> Lemon pie 24cm | D26: Esencia de vainilla | E26: =IFERROR(VLOOKUP($D26,Insumos!$B:$U,D$1,0),"") -> Cm3 | F26: 10 | G26: =IFERROR(VLOOKUP($D26,Insumos!$B:$U,G$1,0)/VLOOKUP($D26,Insumos!$B:$U,F$1,0),"") -> 1.52 | H26: =IFERROR(F26*G26,"") -> 15.2
B27: =IF($D27="","",B26) -> 3 | C27: =IF($D27="","",C26) -> Lemon pie 24cm | D27: Bandeja redonda 24cm rigida | E27: =IFERROR(VLOOKUP($D27,Insumos!$B:$U,D$1,0),"") -> Unidad | F27: 1 | G27: =IFERROR(VLOOKUP($D27,Insumos!$B:$U,G$1,0)/VLOOKUP($D27,Insumos!$B:$U,F$1,0),"") -> 1300 | H27: =IFERROR(F27*G27,"") -> 1300
B28: =IF($D28="","",B27) -> 3 | C28: =IF($D28="","",C27) -> Lemon pie 24cm | D28: Caja maletin kraf 25x25x15 | E28: =IFERROR(VLOOKUP($D28,Insumos!$B:$U,D$1,0),"") -> Unidad | F28: 1 | G28: =IFERROR(VLOOKUP($D28,Insumos!$B:$U,G$1,0)/VLOOKUP($D28,Insumos!$B:$U,F$1,0),"") -> 975 | H28: =IFERROR(F28*G28,"") -> 975
B29: =IF($D29="","",B28) -> 3 | C29: =IF($D29="","",C28) -> Lemon pie 24cm | D29: Limón | E29: =IFERROR(VLOOKUP($D29,Insumos!$B:$U,D$1,0),"") -> Unidad | F29: 2 | G29: =IFERROR(VLOOKUP($D29,Insumos!$B:$U,G$1,0)/VLOOKUP($D29,Insumos!$B:$U,F$1,0),"") -> 180 | H29: =IFERROR(F29*G29,"") -> 360
B30: =IF($D30="","",B29) -> 3 | C30: =IF($D30="","",C29) -> Lemon pie 24cm | D30: Azúcar | E30: =IFERROR(VLOOKUP($D30,Insumos!$B:$U,D$1,0),"") -> Grs | F30: =120+240 -> 360 | G30: =IFERROR(VLOOKUP($D30,Insumos!$B:$U,G$1,0)/VLOOKUP($D30,Insumos!$B:$U,F$1,0),"") -> 1.4 | H30: =IFERROR(F30*G30,"") -> 504
B31: =IF($D31="","",B30) -> 3 | C31: =IF($D31="","",C30) -> Lemon pie 24cm | D31: Mangas descartables N°4 | E31: =IFERROR(VLOOKUP($D31,Insumos!$B:$U,D$1,0),"") -> Unidad | F31: 1 | G31: =IFERROR(VLOOKUP($D31,Insumos!$B:$U,G$1,0)/VLOOKUP($D31,Insumos!$B:$U,F$1,0),"") -> 400 | H31: =IFERROR(F31*G31,"") -> 400
B32: =IF($D32="","",B31) -> 3 | C32: =IF($D32="","",C31) -> Lemon pie 24cm | D32: Gelatina Sin Sabor | E32: =IFERROR(VLOOKUP($D32,Insumos!$B:$U,D$1,0),"") -> Grs | F32: 10 | G32: =IFERROR(VLOOKUP($D32,Insumos!$B:$U,G$1,0)/VLOOKUP($D32,Insumos!$B:$U,F$1,0),"") -> 18 | H32: =IFERROR(F32*G32,"") -> 180
B33: 4 | C33: Lemon pie 12cm | D33: Manteca | E33: =IFERROR(VLOOKUP($D33,Insumos!$B:$U,D$1,0),"") -> Grs | F33: =F22/2 -> 165 | G33: =IFERROR(VLOOKUP($D33,Insumos!$B:$U,G$1,0)/VLOOKUP($D33,Insumos!$B:$U,F$1,0),"") -> 11 | H33: =IFERROR(F33*G33,"") -> 1815
B34: =IF($D34="","",B33) -> 4 | C34: =IF($D34="","",C33) -> Lemon pie 12cm | D34: Harina 0000 | E34: =IFERROR(VLOOKUP($D34,Insumos!$B:$U,D$1,0),"") -> Grs | F34: =F23/2 -> 150 | G34: =IFERROR(VLOOKUP($D34,Insumos!$B:$U,G$1,0)/VLOOKUP($D34,Insumos!$B:$U,F$1,0),"") -> 0.82 | H34: =IFERROR(F34*G34,"") -> 123
B35: =IF($D35="","",B34) -> 4 | C35: =IF($D35="","",C34) -> Lemon pie 12cm | D35: Azúcar impalpable | E35: =IFERROR(VLOOKUP($D35,Insumos!$B:$U,D$1,0),"") -> Grs | F35: =F24/2 -> 60 | G35: =IFERROR(VLOOKUP($D35,Insumos!$B:$U,G$1,0)/VLOOKUP($D35,Insumos!$B:$U,F$1,0),"") -> 1.5 | H35: =IFERROR(F35*G35,"") -> 90
B36: =IF($D36="","",B35) -> 4 | C36: =IF($D36="","",C35) -> Lemon pie 12cm | D36: Huevo | E36: =IFERROR(VLOOKUP($D36,Insumos!$B:$U,D$1,0),"") -> Unidad | F36: =F25/2 -> 4 | G36: =IFERROR(VLOOKUP($D36,Insumos!$B:$U,G$1,0)/VLOOKUP($D36,Insumos!$B:$U,F$1,0),"") -> 166.66667 | H36: =IFERROR(F36*G36,"") -> 666.66667
B37: =IF($D37="","",B36) -> 4 | C37: =IF($D37="","",C36) -> Lemon pie 12cm | D37: Esencia de vainilla | E37: =IFERROR(VLOOKUP($D37,Insumos!$B:$U,D$1,0),"") -> Cm3 | F37: =F26/2 -> 5 | G37: =IFERROR(VLOOKUP($D37,Insumos!$B:$U,G$1,0)/VLOOKUP($D37,Insumos!$B:$U,F$1,0),"") -> 1.52 | H37: =IFERROR(F37*G37,"") -> 7.6
B38: =IF($D38="","",B37) -> 4 | C38: =IF($D38="","",C37) -> Lemon pie 12cm | D38: Bandeja redonda 24cm rigida | E38: =IFERROR(VLOOKUP($D38,Insumos!$B:$U,D$1,0),"") -> Unidad | F38: =F27/2 -> 0.5 | G38: =IFERROR(VLOOKUP($D38,Insumos!$B:$U,G$1,0)/VLOOKUP($D38,Insumos!$B:$U,F$1,0),"") -> 1300 | H38: =IFERROR(F38*G38,"") -> 650
B39: =IF($D39="","",B38) -> 4 | C39: =IF($D39="","",C38) -> Lemon pie 12cm | D39: Caja maletin kraf 25x25x15 | E39: =IFERROR(VLOOKUP($D39,Insumos!$B:$U,D$1,0),"") -> Unidad | F39: =F28/2 -> 0.5 | G39: =IFERROR(VLOOKUP($D39,Insumos!$B:$U,G$1,0)/VLOOKUP($D39,Insumos!$B:$U,F$1,0),"") -> 975 | H39: =IFERROR(F39*G39,"") -> 487.5
B40: =IF($D40="","",B39) -> 4 | C40: =IF($D40="","",C39) -> Lemon pie 12cm | D40: Limón | E40: =IFERROR(VLOOKUP($D40,Insumos!$B:$U,D$1,0),"") -> Unidad | F40: =F29/2 -> 1 | G40: =IFERROR(VLOOKUP($D40,Insumos!$B:$U,G$1,0)/VLOOKUP($D40,Insumos!$B:$U,F$1,0),"") -> 180 | H40: =IFERROR(F40*G40,"") -> 180
...

Sheet Costo x Articulo
B2: Nro. | C2: Artículo | D2: Precio | E2: Bar | F2: Precio de venta recomendado 200% | G2: Costo total | H2: Ganancia Recomendada | I2: Precio de venta | J2: Ganancia | K2: Margen | L2: Doble puro | M2: Promo x2 | N2: Precio unitario promo | O2: Ganancia por unidad promo
B3: 1 | C3: =TEXT(IFERROR(VLOOKUP($B3,Recetas!$B:$C,2,0),""),) -> Budín de limón | D3: 10000 | E3: x | F3: =IFERROR(G3*(1+200%),0) -> 16674.2 | G3: =IF(C3="","",SUMIF(Recetas!$B:$B,'Costo x Articulo'!$B3,Recetas!$H:$H)) -> 5558.0667 | H3: =IFERROR(F3-G3,0) -> 11116.133 | I3: 4100 | J3: =IF(I3="","",I3-G3) -> -1458.0667 | K3: =IFERROR(J3/G3,"") -> -0.26233343
B4: 2 | C4: =TEXT(IFERROR(VLOOKUP($B4,Recetas!$B:$C,2,0),""),) -> Macarrons x 12 unidades | D4: 7000 | E4: x | F4: =IFERROR(G4*(1+200%),0) -> 10173.4 | G4: =IF(C4="","",SUMIF(Recetas!$B:$B,'Costo x Articulo'!$B4,Recetas!$H:$H)) -> 3391.1333 | H4: =IFERROR(F4-G4,0) -> 6782.2667 | I4: 2700 | J4: =IF(I4="","",I4-G4) -> -691.13333 | K4: =IFERROR(J4/G4,"") -> -0.203806
B5: 3 | C5: =TEXT(IFERROR(VLOOKUP($B5,Recetas!$B:$C,2,0),""),) -> Lemon pie 24cm | D5: 16000 | E5: x | F5: =IFERROR(G5*(1+200%),0) -> 27370.6 | G5: =IF(C5="","",SUMIF(Recetas!$B:$B,'Costo x Articulo'!$B5,Recetas!$H:$H)) -> 9123.5333 | H5: =IFERROR(F5-G5,0) -> 18247.067 | I5: 7300 | J5: =IF(I5="","",I5-G5) -> -1823.5333 | K5: =IFERROR(J5/G5,"") -> -0.19987139
B6: 4 | C6: =TEXT(IFERROR(VLOOKUP($B6,Recetas!$B:$C,2,0),""),) -> Lemon pie 12cm | F6: =IFERROR(G6*(1+200%),0) -> 13685.3 | G6: =IF(C6="","",SUMIF(Recetas!$B:$B,'Costo x Articulo'!$B6,Recetas!$H:$H)) -> 4561.7667 | H6: =IFERROR(F6-G6,0) -> 9123.5333 | I6: 2700 | J6: =IF(I6="","",I6-G6) -> -1861.7667 | K6: =IFERROR(J6/G6,"") -> -0.40812405
B7: 5 | C7: =TEXT(IFERROR(VLOOKUP($B7,Recetas!$B:$C,2,0),""),) -> Brownie 20x20cm | F7: =IFERROR(G7*(1+200%),0) -> 22591.983 | G7: =IF(C7="","",SUMIF(Recetas!$B:$B,'Costo x Articulo'!$B7,Recetas!$H:$H)) -> 7530.6611 | H7: =IFERROR(F7-G7,0) -> 15061.322 | I7: 4500 | J7: =IF(I7="","",I7-G7) -> -3030.6611 | K7: =IFERROR(J7/G7,"") -> -0.4024429
B8: 6 | C8: =TEXT(IFERROR(VLOOKUP($B8,Recetas!$B:$C,2,0),""),) -> Torta brownie 20x20cm | D8: 20000 | E8: x | F8: =IFERROR(G8*(1+200%),0) -> 30699.983 | G8: =IF(C8="","",SUMIF(Recetas!$B:$B,'Costo x Articulo'!$B8,Recetas!$H:$H)) -> 10233.328 | H8: =IFERROR(F8-G8,0) -> 20466.656 | I8: 7000 | J8: =IF(I8="","",I8-G8) -> -3233.3278 | K8: =IFERROR(J8/G8,"") -> -0.31596054
B9: 7 | C9: =TEXT(IFERROR(VLOOKUP($B9,Recetas!$B:$C,2,0),""),) -> Tarta Frutillas 24cm | F9: =IFERROR(G9*(1+200%),0) -> 18376 | G9: =IF(C9="","",SUMIF(Recetas!$B:$B,'Costo x Articulo'!$B9,Recetas!$H:$H)) -> 6125.3333 | H9: =IFERROR(F9-G9,0) -> 12250.667 | I9: 5100 | J9: =IF(I9="","",I9-G9) -> -1025.3333 | K9: =IFERROR(J9/G9,"") -> -0.16739225
B10: 8 | C10: =TEXT(IFERROR(VLOOKUP($B10,Recetas!$B:$C,2,0),""),) -> Bombas De DDL | F10: =IFERROR(G10*(1+200%),0) -> 20596.6 | G10: =IF(C10="","",SUMIF(Recetas!$B:$B,'Costo x Articulo'!$B10,Recetas!$H:$H)) -> 6865.5333 | H10: =IFERROR(F10-G10,0) -> 13731.067 | I10: 5400 | J10: =IF(I10="","",I10-G10) -> -1465.5333 | K10: =IFERROR(J10/G10,"") -> -0.21346242
B11: 9 | C11: =TEXT(IFERROR(VLOOKUP($B11,Recetas!$B:$C,2,0),""),) -> bombas De Crema | F11: =IFERROR(G11*(1+200%),0) -> 21016.6 | G11: =IF(C11="","",SUMIF(Recetas!$B:$B,'Costo x Articulo'!$B11,Recetas!$H:$H)) -> 7005.5333 | H11: =IFERROR(F11-G11,0) -> 14011.067 | I11: 5200 | J11: =IF(I11="","",I11-G11) -> -1805.5333 | K11: =IFERROR(J11/G11,"") -> -0.2577296
B12: 10 | C12: =TEXT(IFERROR(VLOOKUP($B12,Recetas!$B:$C,2,0),""),) -> Cookies Chips Chocolatesx15 | D12: 4500 | E12: x | F12: =IFERROR(G12*(1+200%),0) -> 7233.38 | G12: =IF(C12="","",SUMIF(Recetas!$B:$B,'Costo x Articulo'!$B12,Recetas!$H:$H)) -> 2411.1267 | H12: =IFERROR(F12-G12,0) -> 4822.2533 | I12: 1800 | J12: =IF(I12="","",I12-G12) -> -611.12667 | K12: =IFERROR(J12/G12,"") -> -0.25346104
B13: 11 | C13: =TEXT(IFERROR(VLOOKUP($B13,Recetas!$B:$C,2,0),""),) -> Alfajores de Nuez x12 | D13: 8000 | E13: x | F13: =IFERROR(G13*(1+200%),0) -> 10929.5 | G13: =IF(C13="","",SUMIF(Recetas!$B:$B,'Costo x Articulo'!$B13,Recetas!$H:$H)) -> 3643.1667 | H13: =IFERROR(F13-G13,0) -> 7286.3333 | I13: 3300 | J13: =IF(I13="","",I13-G13) -> -343.16667 | K13: =IFERROR(J13/G13,"") -> -0.094194611
B14: 12 | C14: =TEXT(IFERROR(VLOOKUP($B14,Recetas!$B:$C,2,0),""),) -> Tarta de Coco | F14: =IFERROR(G14*(1+200%),0) -> 28632.35 | G14: =IF(C14="","",SUMIF(Recetas!$B:$B,'Costo x Articulo'!$B14,Recetas!$H:$H)) -> 9544.1167 | H14: =IFERROR(F14-G14,0) -> 19088.233 | I14: 6700 | J14: =IF(I14="","",I14-G14) -> -2844.1167 | K14: =IFERROR(J14/G14,"") -> -0.29799685
B15: 13 | C15: =TEXT(IFERROR(VLOOKUP($B15,Recetas!$B:$C,2,0),""),) -> Selva Negra 20 cm | F15: =IFERROR(G15*(1+200%),0) -> 34123.35 | G15: =IF(C15="","",SUMIF(Recetas!$B:$B,'Costo x Articulo'!$B15,Recetas!$H:$H)) -> 11374.45 | H15: =IFERROR(F15-G15,0) -> 22748.9 | I15: 8700 | J15: =IF(I15="","",I15-G15) -> -2674.45 | K15: =IFERROR(J15/G15,"") -> -0.23512785
B16: 14 | C16: =TEXT(IFERROR(VLOOKUP($B16,Recetas!$B:$C,2,0),""),) -> Tiramisu | F16: =IFERROR(G16*(1+200%),0) -> 48748.568 | G16: =IF(C16="","",SUMIF(Recetas!$B:$B,'Costo x Articulo'!$B16,Recetas!$H:$H)) -> 16249.523 | H16: =IFERROR(F16-G16,0) -> 32499.045 | I16: 5100 | J16: =IF(I16="","",I16-G16) -> -11149.523 | K16: =IFERROR(J16/G16,"") -> -0.68614463
B17: 15 | C17: =TEXT(IFERROR(VLOOKUP($B17,Recetas!$B:$C,2,0),""),) -> Cheese Cake 18cm | F17: =IFERROR(G17*(1+200%),0) -> 28119.299 | G17: =IF(C17="","",SUMIF(Recetas!$B:$B,'Costo x Articulo'!$B17,Recetas!$H:$H)) -> 9373.0996 | H17: =IFERROR(F17-G17,0) -> 18746.199 | I17: 4100 | J17: =IF(I17="","",I17-G17) -> -5273.0996 | K17: =IFERROR(J17/G17,"") -> -0.562578
B18: 16 | C18: =TEXT(IFERROR(VLOOKUP($B18,Recetas!$B:$C,2,0),""),) -> Rogel | F18: =IFERROR(G18*(1+200%),0) -> 30949.15 | G18: =IF(C18="","",SUMIF(Recetas!$B:$B,'Costo x Articulo'!$B18,Recetas!$H:$H)) -> 10316.383 | H18: =IFERROR(F18-G18,0) -> 20632.767 | I18: 8300 | J18: =IF(I18="","",I18-G18) -> -2016.3833 | K18: =IFERROR(J18/G18,"") -> -0.19545448
B19: 17 | C19: =TEXT(IFERROR(VLOOKUP($B19,Recetas!$B:$C,2,0),""),) -> Cheese Cake DDL 18cm | F19: =IFERROR(G19*(1+200%),0) -> 28072.512 | G19: =IF(C19="","",SUMIF(Recetas!$B:$B,'Costo x Articulo'!$B19,Recetas!$H:$H)) -> 9357.504 | H19: =IFERROR(F19-G19,0) -> 18715.008 | I19: 4100 | J19: =IF(I19="","",I19-G19) -> -5257.504 | K19: =IFERROR(J19/G19,"") -> -0.56184897
B20: 18 | C20: =TEXT(IFERROR(VLOOKUP($B20,Recetas!$B:$C,2,0),""),) -> Pastafrola | F20: =IFERROR(G20*(1+200%),0) -> 18075.35 | G20: =IF(C20="","",SUMIF(Recetas!$B:$B,'Costo x Articulo'!$B20,Recetas!$H:$H)) -> 6025.1167 | H20: =IFERROR(F20-G20,0) -> 12050.233 | I20: 2900 | J20: =IF(I20="","",I20-G20) -> -3125.1167 | K20: =IFERROR(J20/G20,"") -> -0.51868152
B21: 19 | C21: =TEXT(IFERROR(VLOOKUP($B21,Recetas!$B:$C,2,0),""),) -> Tarta Ricota | F21: =IFERROR(G21*(1+200%),0) -> 24660.35 | G21: =IF(C21="","",SUMIF(Recetas!$B:$B,'Costo x Articulo'!$B21,Recetas!$H:$H)) -> 8220.1167 | H21: =IFERROR(F21-G21,0) -> 16440.233 | I21: 4500 | J21: =IF(I21="","",I21-G21) -> -3720.1167 | K21: =IFERROR(J21/G21,"") -> -0.45256251
B22: 20 | C22: =TEXT(IFERROR(VLOOKUP($B22,Recetas!$B:$C,2,0),""),) -> Tarta Frutos Secos | F22: =IFERROR(G22*(1+200%),0) -> 27530.75 | G22: =IF(C22="","",SUMIF(Recetas!$B:$B,'Costo x Articulo'!$B22,Recetas!$H:$H)) -> 9176.9167 | H22: =IFERROR(F22-G22,0) -> 18353.833 | I22: 7500 | J22: =IF(I22="","",I22-G22) -> -1676.9167 | K22: =IFERROR(J22/G22,"") -> -0.18273204
B23: 21 | C23: =TEXT(IFERROR(VLOOKUP($B23,Recetas!$B:$C,2,0),""),) -> Alfajor Marplatense | F23: =IFERROR(G23*(1+200%),0) -> 27365.18 | G23: =IF(C23="","",SUMIF(Recetas!$B:$B,'Costo x Articulo'!$B23,Recetas!$H:$H)) -> 9121.7267 | H23: =IFERROR(F23-G23,0) -> 18243.453 | I23: 6800 | J23: =IF(I23="","",I23-G23) -> -2321.7267 | K23: =IFERROR(J23/G23,"") -> -0.2545271
B24: 22 | C24: =TEXT(IFERROR(VLOOKUP($B24,Recetas!$B:$C,2,0),""),) -> Alfajor Maicena | F24: =IFERROR(G24*(1+200%),0) -> 16863.59 | G24: =IF(C24="","",SUMIF(Recetas!$B:$B,'Costo x Articulo'!$B24,Recetas!$H:$H)) -> 5621.1967 | H24: =IFERROR(F24-G24,0) -> 11242.393 | I24: 2500 | J24: =IF(I24="","",I24-G24) -> -3121.1967 | K24: =IFERROR(J24/G24,"") -> -0.55525484
B25: 23 | C25: =TEXT(IFERROR(VLOOKUP($B25,Recetas!$B:$C,2,0),""),) -> Tarta de Manzana 22cm | D25: 13000 | E25: x | F25: =IFERROR(G25*(1+200%),0) -> 20118.35 | G25: =IF(C25="","",SUMIF(Recetas!$B:$B,'Costo x Articulo'!$B25,Recetas!$H:$H)) -> 6706.1167 | H25: =IFERROR(F25-G25,0) -> 13412.233 | I25: 5600 | J25: =IF(I25="","",I25-G25) -> -1106.1167 | K25: =IFERROR(J25/G25,"") -> -0.16494146
B26: 24 | C26: =TEXT(IFERROR(VLOOKUP($B26,Recetas!$B:$C,2,0),""),) -> Chocotorta Redonda | F26: =IFERROR(G26*(1+200%),0) -> 48885.179 | G26: =IF(C26="","",SUMIF(Recetas!$B:$B,'Costo x Articulo'!$B26,Recetas!$H:$H)) -> 16295.06 | H26: =IFERROR(F26-G26,0) -> 32590.119 | I26: 8100 | J26: =IF(I26="","",I26-G26) -> -8195.0595 | K26: =IFERROR(J26/G26,"") -> -0.50291682
B27: 25 | C27: =TEXT(IFERROR(VLOOKUP($B27,Recetas!$B:$C,2,0),""),) -> Doble Cake | F27: =IFERROR(G27*(1+200%),0) -> 62970.109 | G27: =IF(C27="","",SUMIF(Recetas!$B:$B,'Costo x Articulo'!$B27,Recetas!$H:$H)) -> 20990.036 | H27: =IFERROR(F27-G27,0) -> 41980.073 | I27: 12100 | J27: =IF(I27="","",I27-G27) -> -8890.0363 | K27: =IFERROR(J27/G27,"") -> -0.42353601
B28: 26 | C28: =TEXT(IFERROR(VLOOKUP($B28,Recetas!$B:$C,2,0),""),) -> Des- DIA DE LA MADRE | F28: =IFERROR(G28*(1+200%),0) -> 957 | G28: =IF(C28="","",SUMIF(Recetas!$B:$B,'Costo x Articulo'!$B28,Recetas!$H:$H)) -> 319 | H28: =IFERROR(F28-G28,0) -> 638 | I28: 1500 | J28: =IF(I28="","",I28-G28) -> 1181 | K28: =IFERROR(J28/G28,"") -> 3.7021944
B29: 27 | C29: =TEXT(IFERROR(VLOOKUP($B29,Recetas!$B:$C,2,0),""),) -> Desayuno 108 | F29: =IFERROR(G29*(1+200%),0) -> 30377.64 | G29: =IF(C29="","",SUMIF(Recetas!$B:$B,'Costo x Articulo'!$B29,Recetas!$H:$H)) -> 10125.88 | H29: =IFERROR(F29-G29,0) -> 20251.76 | I29: 480 | J29: =IF(I29="","",I29-G29) -> -9645.88 | K29: =IFERROR(J29/G29,"") -> -0.95259671 | L29: =#REF!*120 -> #REF!
B30: 28 | C30: =TEXT(IFERROR(VLOOKUP($B30,Recetas!$B:$C,2,0),""),) -> Cookies decoradas x 12u | F30: =IFERROR(G30*(1+200%),0) -> 19228 | G30: =IF(C30="","",SUMIF(Recetas!$B:$B,'Costo x Articulo'!$B30,Recetas!$H:$H)) -> 6409.3333 | H30: =IFERROR(F30-G30,0) -> 12818.667 | I30: 10000 | J30: =IF(I30="","",I30-G30) -> 3590.6667 | K30: =IFERROR(J30/G30,"") -> 0.56022467
B31: 29 | C31: =TEXT(IFERROR(VLOOKUP($B31,Recetas!$B:$C,2,0),""),) -> Chipa 1/2 kg | F31: =IFERROR(G31*(1+200%),0) -> 24577 | G31: =IF(C31="","",SUMIF(Recetas!$B:$B,'Costo x Articulo'!$B31,Recetas!$H:$H)) -> 8192.3333 | H31: =IFERROR(F31-G31,0) -> 16384.667 | I31: 2500 | J31: =IF(I31="","",I31-G31) -> -5692.3333 | K31: =IFERROR(J31/G31,"") -> -0.69483664
B32: 30 | C32: =TEXT(IFERROR(VLOOKUP($B32,Recetas!$B:$C,2,0),""),) -> Pan Saborizado | F32: =IFERROR(G32*(1+200%),0) -> 1967.1 | G32: =IF(C32="","",SUMIF(Recetas!$B:$B,'Costo x Articulo'!$B32,Recetas!$H:$H)) -> 655.7 | H32: =IFERROR(F32-G32,0) -> 1311.4 | I32: 800 | J32: =IF(I32="","",I32-G32) -> 144.3 | K32: =IFERROR(J32/G32,"") -> 0.22007015
B33: 31 | C33: =TEXT(IFERROR(VLOOKUP($B33,Recetas!$B:$C,2,0),""),) -> Pan Trenzado | F33: =IFERROR(G33*(1+200%),0) -> 3662 | G33: =IF(C33="","",SUMIF(Recetas!$B:$B,'Costo x Articulo'!$B33,Recetas!$H:$H)) -> 1220.6667 | H33: =IFERROR(F33-G33,0) -> 2441.3333 | I33: 1000 | J33: =IF(I33="","",I33-G33) -> -220.66667 | K33: =IFERROR(J33/G33,"") -> -0.18077553
B34: 32 | C34: =TEXT(IFERROR(VLOOKUP($B34,Recetas!$B:$C,2,0),""),) -> Halloween | F34: =IFERROR(G34*(1+200%),0) -> 22101.142 | G34: =IF(C34="","",SUMIF(Recetas!$B:$B,'Costo x Articulo'!$B34,Recetas!$H:$H)) -> 7367.0472 | H34: =IFERROR(F34-G34,0) -> 14734.094 | J34: =IF(I34="","",I34-G34) | K34: =IFERROR(J34/G34,"") -> 0
B35: 33 | C35: =TEXT(IFERROR(VLOOKUP($B35,Recetas!$B:$C,2,0),""),) -> Frambuesas Grandes | F35: =IFERROR(G35*(1+200%),0) -> 1112 | G35: =IF(C35="","",SUMIF(Recetas!$B:$B,'Costo x Articulo'!$B35,Recetas!$H:$H)) -> 370.66667 | H35: =IFERROR(F35-G35,0) -> 741.33333 | I35: 350 | J35: =IF(I35="","",I35-G35) -> -20.666667 | K35: =IFERROR(J35/G35,"") -> -0.055755396
B36: 34 | C36: =TEXT(IFERROR(VLOOKUP($B36,Recetas!$B:$C,2,0),""),) -> Frambuesas chicas | F36: =IFERROR(G36*(1+200%),0) -> 572 | G36: =IF(C36="","",SUMIF(Recetas!$B:$B,'Costo x Articulo'!$B36,Recetas!$H:$H)) -> 190.66667 | H36: =IFERROR(F36-G36,0) -> 381.33333 | I36: 250 | J36: =IF(I36="","",I36-G36) -> 59.333333 | K36: =IFERROR(J36/G36,"") -> 0.31118881
B37: 35 | C37: =TEXT(IFERROR(VLOOKUP($B37,Recetas!$B:$C,2,0),""),) -> desayuno completo | F37: =IFERROR(G37*(1+200%),0) -> 31093.983 | G37: =IF(C37="","",SUMIF(Recetas!$B:$B,'Costo x Articulo'!$B37,Recetas!$H:$H)) -> 10364.661 | H37: =IFERROR(F37-G37,0) -> 20729.322 | I37: 8000 | J37: =IF(I37="","",I37-G37) -> -2364.6611 | K37: =IFERROR(J37/G37,"") -> -0.2281465
B38: 36 | C38: =TEXT(IFERROR(VLOOKUP($B38,Recetas!$B:$C,2,0),""),) -> Pan Dulce 700 gramos | F38: =IFERROR(G38*(1+200%),0) -> 23033.57 | G38: =IF(C38="","",SUMIF(Recetas!$B:$B,'Costo x Articulo'!$B38,Recetas!$H:$H)) -> 7677.8567 | H38: =IFERROR(F38-G38,0) -> 15355.713 | I38: 5800 | J38: =IF(I38="","",I38-G38) -> -1877.8567 | K38: =IFERROR(J38/G38,"") -> -0.24458084
B39: 37 | C39: =TEXT(IFERROR(VLOOKUP($B39,Recetas!$B:$C,2,0),""),) | F39: =IFERROR(G39*(1+200%),0) -> 0 | G39: =IF(C39="","",SUMIF(Recetas!$B:$B,'Costo x Articulo'!$B39,Recetas!$H:$H)) | H39: =IFERROR(F39-G39,0) -> 0 | I39: 1400 | J39: =IF(I39="","",I39-G39) -> 1400 | K39: =IFERROR(J39/G39,"")
B40: 38 | C40: =TEXT(IFERROR(VLOOKUP($B40,Recetas!$B:$C,2,0),""),) -> Pan Dulce 1 KG | F40: =IFERROR(G40*(1+200%),0) -> 20572.82 | G40: =IF(C40="","",SUMIF(Recetas!$B:$B,'Costo x Articulo'!$B40,Recetas!$H:$H)) -> 6857.6067 | H40: =IFERROR(F40-G40,0) -> 13715.213 | I40: 1600 | J40: =IF(I40="","",I40-G40) -> -5257.6067 | K40: =IFERROR(J40/G40,"") -> -0.76668245
B41: 39 | C41: =TEXT(IFERROR(VLOOKUP($B41,Recetas!$B:$C,2,0),""),) -> box dia del medico | F41: =IFERROR(G41*(1+200%),0) -> 19274.2 | G41: =IF(C41="","",SUMIF(Recetas!$B:$B,'Costo x Articulo'!$B41,Recetas!$H:$H)) -> 6424.7333 | H41: =IFERROR(F41-G41,0) -> 12849.467 | I41: 1900 | J41: =IF(I41="","",I41-G41) -> -4524.7333 | K41: =IFERROR(J41/G41,"") -> -0.70426788
...

Sheet Bar
L2: =SUM(L8:L26) -> 58580 | M2: =SUM(M8:M26) -> -286739.16 | P2: =SUM(P8:P26) -> 702960 | Q2: =SUM(Q8:Q26) -> -2293913.3
K6: Por pedido | O6: Por Mes (12 pedidos)
B7: Nro. | C7: Artículo | D7: Costo | E7: Precio minorista | F7: Margen minorista | H7: Precio mayorista | I7: Margen mayorista | K7: Cantidad | L7: Venta Bruta | M7: Ganancia | O7: Cantidad | P7: Venta Bruta | Q7: Ganancia | R7: %
B8: 1 | C8: Budín Limón | D8: ='Costo x Articulo'!G3 -> 5558.0667 | E8: 12000 | F8: =IFERROR((E8-D8)/D8,0) -> 1.1590241 | H8: 1000 | I8: =IFERROR((H8-D8)/D8,0) -> -0.82008132 | K8: 3 | L8: =H8*K8 -> 3000 | M8: =K8*(H8-D8) -> -13674.2 | O8: =K8*12 -> 36 | P8: =L8*12 -> 36000 | Q8: =M8*8 -> -109393.6 | R8: =Q8/$Q$2 -> 0.047688638 | T8: =H8*1.1 -> 1100
B9: 2 | C9: Budín zanahoria | D9: =D8 -> 5558.0667 | E9: =E8 -> 12000 | F9: =IFERROR((E9-D9)/D9,0) -> 1.1590241 | H9: =H8 -> 1000 | I9: =IFERROR((H9-D9)/D9,0) -> -0.82008132 | K9: 3 | L9: =L8 -> 3000 | M9: =K9*(H9-D9) -> -13674.2 | O9: =K9*12 -> 36 | P9: =L9*12 -> 36000 | Q9: =M9*8 -> -109393.6 | R9: =Q9/$Q$2 -> 0.047688638 | T9: =H9*1.1 -> 1100
B10: 3 | C10: Budín marmolado | D10: =D9 -> 5558.0667 | E10: =E9 -> 12000 | F10: =IFERROR((E10-D10)/D10,0) -> 1.1590241 | H10: =H9 -> 1000 | I10: =IFERROR((H10-D10)/D10,0) -> -0.82008132 | K10: 3 | L10: =L9 -> 3000 | M10: =K10*(H10-D10) -> -13674.2 | O10: =K10*12 -> 36 | P10: =L10*12 -> 36000 | Q10: =M10*8 -> -109393.6 | R10: =Q10/$Q$2 -> 0.047688638 | T10: =H10*1.1 -> 1100
B11: 4 | C11: Budín frutos secos | D11: ='Costo x Articulo'!G126 -> 6604.7333 | E11: 15000 | F11: =IFERROR((E11-D11)/D11,0) -> 1.2710985 | H11: =H10 -> 1000 | I11: =IFERROR((H11-D11)/D11,0) -> -0.84859343 | K11: =K10 -> 3 | L11: =L10 -> 3000 | M11: =K11*(H11-D11) -> -16814.2 | O11: =K11*12 -> 36 | P11: =L11*12 -> 36000 | Q11: =M11*8 -> -134513.6 | R11: =Q11/$Q$2 -> 0.058639358 | T11: =H11*1.1 -> 1100
B12: 5 | C12: Lemon Pie | D12: ='Costo x Articulo'!G5/6 -> 1520.5889 | E12: 3000 | F12: =IFERROR((E12-D12)/D12,0) -> 0.97291985 | H12: 350 | I12: =IFERROR((H12-D12)/D12,0) -> -0.76982602 | K12: 12 | L12: =H12*K12 -> 4200 | M12: =K12*(H12-D12) -> -14047.067 | O12: =K12*12 -> 144 | P12: =L12*12 -> 50400 | Q12: =M12*8 -> -112376.53 | R12: =Q12/$Q$2 -> 0.048989007 | T12: =H12*1.1 -> 385
B13: 6 | C13: Browrnie Oreo | D13: ='Costo x Articulo'!G55/6 -> 2428.888 | E13: 4500 | F13: =IFERROR((E13-D13)/D13,0) -> 0.8526997 | H13: =H12 -> 350 | I13: =IFERROR((H13-D13)/D13,0) -> -0.85590113 | K13: 24 | L13: =H13*K13 -> 8400 | M13: =K13*(H13-D13) -> -49893.311 | O13: =K13*12 -> 288 | P13: =L13*12 -> 100800 | Q13: =M13*8 -> -399146.49 | R13: =Q13/$Q$2 -> 0.17400243 | T13: =H13*1.1 -> 385
B14: 7 | C14: Chocotorta | D14: ='Costo x Articulo'!G127/6 -> 2817.2619 | E14: 5000 | F14: =IFERROR((E14-D14)/D14,0) -> 0.77477287 | H14: =H13 -> 350 | I14: =IFERROR((H14-D14)/D14,0) -> -0.8757659 | K14: 24 | L14: =H14*K14 -> 8400 | M14: =K14*(H14-D14) -> -59214.286 | O14: =K14*12 -> 288 | P14: =L14*12 -> 100800 | Q14: =M14*8 -> -473714.29 | R14: =Q14/$Q$2 -> 0.20650924 | T14: =H14*1.1 -> 385
B15: 8 | C15: Cheese Cake Frutos rojos | D15: ='Costo x Articulo'!G44/6 -> 2541.6553 | E15: 5000 | F15: =IFERROR((E15-D15)/D15,0) -> 0.96722191 | H15: =H14 -> 350 | I15: =IFERROR((H15-D15)/D15,0) -> -0.86229447 | K15: 24 | L15: =H15*K15 -> 8400 | M15: =K15*(H15-D15) -> -52599.727 | O15: =K15*12 -> 288 | P15: =L15*12 -> 100800 | Q15: =M15*8 -> -420797.82 | R15: =Q15/$Q$2 -> 0.18344103 | T15: =H15*1.1 -> 385
B16: 9 | C16: Torta Oreo | D16: ='Costo x Articulo'!G67/6 -> 2985.8333 | E16: 5000 | F16: =IFERROR((E16-D16)/D16,0) -> 0.67457438 | H16: =H15 -> 350 | I16: =IFERROR((H16-D16)/D16,0) -> -0.88277979 | K16: 12 | L16: =H16*K16 -> 4200 | M16: =K16*(H16-D16) -> -31630 | O16: =K16*12 -> 144 | P16: =L16*12 -> 50400 | Q16: =M16*8 -> -253040 | R16: =Q16/$Q$2 -> 0.11030931 | T16: =H16*1.1 -> 385
B17: 10 | C17: Apple Crumble | D17: ='Costo x Articulo'!G25/6 -> 1117.6861 | E17: 2500 | F17: =IFERROR((E17-D17)/D17,0) -> 1.2367639 | H17: =H16 -> 350 | I17: =IFERROR((H17-D17)/D17,0) -> -0.68685305 | K17: 24 | L17: =H17*K17 -> 8400 | M17: =K17*(H17-D17) -> -18424.467 | O17: =K17*12 -> 288 | P17: =L17*12 -> 100800 | Q17: =M17*8 -> -147395.73 | R17: =Q17/$Q$2 -> 0.064255147 | T17: =H17*1.1 -> 385
B18: 11 | C18: Macarrons x12 | D18: ='Costo x Articulo'!G68/4 -> 1918.375 | E18: 3000 | F18: =IFERROR((E18-D18)/D18,0) -> 0.56382355 | H18: =75*12 -> 900 | I18: =IFERROR((H18-D18)/D18,0) -> -0.53085294 | K18: 4 | L18: =H18*K18 -> 3600 | M18: =K18*(H18-D18) -> -4073.5 | O18: =K18*12 -> 48 | P18: =L18*12 -> 43200 | Q18: =M18*8 -> -32588 | R18: =Q18/$Q$2 -> 0.014206291 | T18: =H18*1.1 -> 990
B19: 12 | C19: Carrot Cake | D19: ='Costo x Articulo'!G74/8 -> 694.49405 | E19: 2400 | F19: =IFERROR((E19-D19)/D19,0) -> 2.4557532 | H19: =H17 -> 350 | I19: =IFERROR((H19-D19)/D19,0) -> -0.496036 | L19: =H19*K19 -> 0 | M19: =K19*(H19-D19) -> 0 | P19: =L19*12 -> 0 | Q19: =M19*8 -> 0 | R19: =Q19/$Q$2 -> 0
B20: 13 | C20: Pastafrola 7cm x 7cm | D20: =SUM(Recetas!H176:H184)*2/6/10*7 -> 873.56889 | E20: 2000 | F20: =IFERROR((E20-D20)/D20,0) -> 1.2894588 | H20: 120 | I20: =IFERROR((H20-D20)/D20,0) -> -0.86263247 | L20: =H20*K20 -> 0 | M20: =K20*(H20-D20) -> 0 | O20: =K20*12 -> 0 | P20: =L20*12 -> 0 | Q20: =M20*8 -> 0 | R20: =Q20/$Q$2 -> 0
B21: 14 | C21: Ricota 7cm x 7cm | D21: =SUM(Recetas!H188:H196)*2/6/10*7 -> 1385.7356 | E21: 2600 | F21: =IFERROR((E21-D21)/D21,0) -> 0.87625986 | H21: 180 | I21: =IFERROR((H21-D21)/D21,0) -> -0.87010509 | L21: =H21*K21 -> 0 | M21: =K21*(H21-D21) -> 0 | O21: =K21*12 -> 0 | P21: =L21*12 -> 0 | Q21: =M21*8 -> 0 | R21: =Q21/$Q$2 -> 0
B22: 15 | C22: Coco y dulce de leche 7cm x 7cm | D22: =SUM(Recetas!H104:H112)*2/6/10*7 -> 1694.6689 | E22: 2900 | F22: =IFERROR((E22-D22)/D22,0) -> 0.71124874 | H22: 200 | I22: =IFERROR((H22-D22)/D22,0) -> -0.88198285 | L22: =H22*K22 -> 0 | M22: =K22*(H22-D22) -> 0 | O22: =K22*12 -> 0 | P22: =L22*12 -> 0 | Q22: =M22*8 -> 0 | R22: =Q22/$Q$2 -> 0
B23: 16 | C23: Torta cumpleaños Selva Negra 20cm | D23: =SUM(Recetas!H116:H124) -> 9093.2 | E23: 22500 | F23: =IFERROR((E23-D23)/D23,0) -> 1.4743765 | H23: 2000 | I23: =IFERROR((H23-D23)/D23,0) -> -0.78005543 | L23: =H23*K23 -> 0 | M23: =K23*(H23-D23) -> 0 | O23: =K23*12 -> 0 | P23: =L23*12 -> 0 | Q23: =M23*8 -> 0 | R23: =Q23/$Q$2 -> 0
B24: 17 | C24: Pan de Campo | D24: =SUM(Recetas!H722:H725) -> 685.5 | E24: 1500 | F24: =IFERROR((E24-D24)/D24,0) -> 1.1881838 | H24: 150 | I24: =IFERROR((H24-D24)/D24,0) -> -0.78118162 | L24: =H24*K24 -> 0 | M24: =K24*(H24-D24) -> 0 | P24: =L24*12 -> 0 | Q24: =M24*8 -> 0 | R24: =Q24/$Q$2 -> 0
B25: 18 | C25: cookies chips de chocolate x 12 | E25: 1100 | F25: =IFERROR((E25-D25)/D25,0) -> 0 | H25: 980 | I25: =IFERROR((H25-D25)/D25,0) -> 0 | K25: 1 | L25: =H25*K25 -> 980 | M25: =K25*(H25-D25) -> 980 | O25: 6 | P25: =L25*12 -> 11760 | Q25: =M25*8 -> 7840
F26: =IFERROR((E26-D26)/D26,0) -> 0 | I26: =IFERROR((H26-D26)/D26,0) -> 0 | Q26: =M26*8 -> 0

Sheet Catering
C2: Catering para 50 personas | D2: Importe | E2: Costo
B3: canape de atun x 50 unidades | C3: Canapé de Atún x 50u. | E3: =SUMIF(Recetas!C:C,Catering!B3,Recetas!H:H) -> 25370
B4: canape de queso crema y cibulet x 50 | C4: Canapé de Queso crema y ciboullet x 50u. | E4: =SUMIF(Recetas!C:C,Catering!B4,Recetas!H:H) -> 19400
B5: empanadas copetin x 24 | C5: Empanadas Copetín x 50u. | E5: =SUMIF(Recetas!C:C,Catering!B5,Recetas!H:H)/24*50 -> 38229.167
B6: figacitas con bondiola | C6: Figacitas de manteca con bondiola x 50u. | E6: =SUMIF(Recetas!C:C,Catering!B6,Recetas!H:H) -> 44966.667
B7: pinchos capresse | C7: Pincho Capresse x 50u. | E7: =SUMIF(Recetas!C:C,Catering!B7,Recetas!H:H) -> 24875
B8: Chip de pollo x50 | C8: Chips de pollo x 50u. | E8: =SUM(Recetas!H953:H960)/12*50 -> 62901.667
B9: Chip de fiambre x50 | C9: Chips de jamón y queso x 50u. | E9: =SUM(Recetas!H946:H952)/12*50 -> 30297.5
B10: pizzetas x 12 | C10: Pizzetas x50u. | E10: =SUM(Recetas!H710:H713)/12*50 -> 5036.6071 | L10: =281*2 -> 562
D11: =SUM(D3:D10) -> 0 | E11: =SUM(E3:E10) -> 251076.61
E12: =D11/E11-1 -> -1

Sheet Ventas Bar
B3: N° | C3: Fecha | D3: Mes | E3: Nro. | F3: Artículo | G3: Unidades | H3: Costo Total | I3: Venta Total | J3: Ganancia
B4: 1 | C4: 44637 | D4: =IFERROR(MONTH(C4),"") -> 3 | E4: 1 | F4: =IFERROR(VLOOKUP(E4,Bar!$B:$C,2,0),"") -> Budín Limón | G4: 3 | H4: =IFERROR(IFERROR(VLOOKUP(E4,Bar!$B:$D,3,0),"")*G4,"") -> 16674.2 | I4: 2400 | J4: =IFERROR(I4-H4,"") -> -14274.2
B5: 1 | C5: 44637 | D5: =IFERROR(MONTH(C5),"") -> 3 | E5: 2 | F5: =IFERROR(VLOOKUP(E5,Bar!$B:$C,2,0),"") -> Budín zanahoria | G5: 3 | H5: =IFERROR(IFERROR(VLOOKUP(E5,Bar!$B:$D,3,0),"")*G5,"") -> 16674.2 | I5: 2400 | J5: =IFERROR(I5-H5,"") -> -14274.2
B6: 1 | C6: 44637 | D6: =IFERROR(MONTH(C6),"") -> 3 | E6: 3 | F6: =IFERROR(VLOOKUP(E6,Bar!$B:$C,2,0),"") -> Budín marmolado | G6: 3 | H6: =IFERROR(IFERROR(VLOOKUP(E6,Bar!$B:$D,3,0),"")*G6,"") -> 16674.2 | I6: 2400 | J6: =IFERROR(I6-H6,"") -> -14274.2
B7: 1 | C7: 44637 | D7: =IFERROR(MONTH(C7),"") -> 3 | E7: 4 | F7: =IFERROR(VLOOKUP(E7,Bar!$B:$C,2,0),"") -> Budín frutos secos | G7: 3 | H7: =IFERROR(IFERROR(VLOOKUP(E7,Bar!$B:$D,3,0),"")*G7,"") -> 19814.2 | I7: 2400 | J7: =IFERROR(I7-H7,"") -> -17414.2
B8: 1 | C8: 44637 | D8: =IFERROR(MONTH(C8),"") -> 3 | E8: 11 | F8: =IFERROR(VLOOKUP(E8,Bar!$B:$C,2,0),"") -> Macarrons x12 | G8: 2 | H8: =IFERROR(IFERROR(VLOOKUP(E8,Bar!$B:$D,3,0),"")*G8,"") -> 3836.75 | I8: 1000 | J8: =IFERROR(I8-H8,"") -> -2836.75
B9: =B8+1 -> 2 | C9: 44638 | D9: =IFERROR(MONTH(C9),"") -> 3 | E9: 8 | F9: =IFERROR(VLOOKUP(E9,Bar!$B:$C,2,0),"") -> Cheese Cake Frutos rojos | G9: 24 | H9: =IFERROR(IFERROR(VLOOKUP(E9,Bar!$B:$D,3,0),"")*G9,"") -> 60999.727 | I9: 6480 | J9: =IFERROR(I9-H9,"") -> -54519.727
B10: 2 | C10: =IFERROR(IF(B10=B9,C9,""),"") -> 44638 | D10: =IFERROR(MONTH(C10),"") -> 3 | E10: 5 | F10: =IFERROR(VLOOKUP(E10,Bar!$B:$C,2,0),"") -> Lemon Pie | G10: 12 | H10: =IFERROR(IFERROR(VLOOKUP(E10,Bar!$B:$D,3,0),"")*G10,"") -> 18247.067 | I10: 3240 | J10: =IFERROR(I10-H10,"") -> -15007.067
B11: 2 | C11: =IFERROR(IF(B11=B10,C10,""),"") -> 44638 | D11: =IFERROR(MONTH(C11),"") -> 3 | E11: 6 | F11: =IFERROR(VLOOKUP(E11,Bar!$B:$C,2,0),"") -> Browrnie Oreo | G11: 24 | H11: =IFERROR(IFERROR(VLOOKUP(E11,Bar!$B:$D,3,0),"")*G11,"") -> 58293.311 | I11: 6480 | J11: =IFERROR(I11-H11,"") -> -51813.311
B12: 2 | C12: =IFERROR(IF(B12=B11,C11,""),"") -> 44638 | D12: =IFERROR(MONTH(C12),"") -> 3 | E12: 7 | F12: =IFERROR(VLOOKUP(E12,Bar!$B:$C,2,0),"") -> Chocotorta | G12: 24 | H12: =IFERROR(IFERROR(VLOOKUP(E12,Bar!$B:$D,3,0),"")*G12,"") -> 67614.286 | I12: 6480 | J12: =IFERROR(I12-H12,"") -> -61134.286
B13: 2 | C13: =IFERROR(IF(B13=B12,C12,""),"") -> 44638 | D13: =IFERROR(MONTH(C13),"") -> 3 | E13: 9 | F13: =IFERROR(VLOOKUP(E13,Bar!$B:$C,2,0),"") -> Torta Oreo | G13: 12 | H13: =IFERROR(IFERROR(VLOOKUP(E13,Bar!$B:$D,3,0),"")*G13,"") -> 35830 | I13: 3240 | J13: =IFERROR(I13-H13,"") -> -32590
B14: 2 | C14: =IFERROR(IF(B14=B13,C13,""),"") -> 44638 | D14: =IFERROR(MONTH(C14),"") -> 3 | E14: 10 | F14: =IFERROR(VLOOKUP(E14,Bar!$B:$C,2,0),"") -> Apple Crumble | G14: 17 | H14: =IFERROR(IFERROR(VLOOKUP(E14,Bar!$B:$D,3,0),"")*G14,"") -> 19000.664 | I14: 4590 | J14: =IFERROR(I14-H14,"") -> -14410.664
B15: 2 | C15: =IFERROR(IF(B15=B14,C14,""),"") -> 44638 | D15: =IFERROR(MONTH(C15),"") -> 3 | E15: 1 | F15: =IFERROR(VLOOKUP(E15,Bar!$B:$C,2,0),"") -> Budín Limón | G15: 3 | H15: =IFERROR(IFERROR(VLOOKUP(E15,Bar!$B:$D,3,0),"")*G15,"") -> 16674.2 | I15: 2400 | J15: =IFERROR(I15-H15,"") -> -14274.2
B16: 2 | C16: =IFERROR(IF(B16=B15,C15,""),"") -> 44638 | D16: =IFERROR(MONTH(C16),"") -> 3 | E16: 2 | F16: =IFERROR(VLOOKUP(E16,Bar!$B:$C,2,0),"") -> Budín zanahoria | G16: 3 | H16: =IFERROR(IFERROR(VLOOKUP(E16,Bar!$B:$D,3,0),"")*G16,"") -> 16674.2 | I16: 2400 | J16: =IFERROR(I16-H16,"") -> -14274.2
B17: 2 | C17: =IFERROR(IF(B17=B16,C16,""),"") -> 44638 | D17: =IFERROR(MONTH(C17),"") -> 3 | E17: 3 | F17: =IFERROR(VLOOKUP(E17,Bar!$B:$C,2,0),"") -> Budín marmolado | G17: 3 | H17: =IFERROR(IFERROR(VLOOKUP(E17,Bar!$B:$D,3,0),"")*G17,"") -> 16674.2 | I17: 2400 | J17: =IFERROR(I17-H17,"") -> -14274.2
B18: 2 | C18: =IFERROR(IF(B18=B17,C17,""),"") -> 44638 | D18: =IFERROR(MONTH(C18),"") -> 3 | E18: 4 | F18: =IFERROR(VLOOKUP(E18,Bar!$B:$C,2,0),"") -> Budín frutos secos | G18: 3 | H18: =IFERROR(IFERROR(VLOOKUP(E18,Bar!$B:$D,3,0),"")*G18,"") -> 19814.2 | I18: 2400 | J18: =IFERROR(I18-H18,"") -> -17414.2
B19: 2 | C19: =IFERROR(IF(B19=B18,C18,""),"") -> 44638 | D19: =IFERROR(MONTH(C19),"") -> 3 | E19: 11 | F19: =IFERROR(VLOOKUP(E19,Bar!$B:$C,2,0),"") -> Macarrons x12 | G19: 4 | H19: =IFERROR(IFERROR(VLOOKUP(E19,Bar!$B:$D,3,0),"")*G19,"") -> 7673.5 | I19: 2000 | J19: =IFERROR(I19-H19,"") -> -5673.5
B20: =B19+1 -> 3 | C20: 44641 | D20: =IFERROR(MONTH(C20),"") -> 3 | E20: 8 | F20: =IFERROR(VLOOKUP(E20,Bar!$B:$C,2,0),"") -> Cheese Cake Frutos rojos | G20: 24 | H20: =IFERROR(IFERROR(VLOOKUP(E20,Bar!$B:$D,3,0),"")*G20,"") -> 60999.727 | I20: 6480 | J20: =IFERROR(I20-H20,"") -> -54519.727
B21: 3 | C21: =IFERROR(IF(B21=B20,C20,""),"") -> 44641 | D21: =IFERROR(MONTH(C21),"") -> 3 | E21: 5 | F21: =IFERROR(VLOOKUP(E21,Bar!$B:$C,2,0),"") -> Lemon Pie | G21: 12 | H21: =IFERROR(IFERROR(VLOOKUP(E21,Bar!$B:$D,3,0),"")*G21,"") -> 18247.067 | I21: 3240 | J21: =IFERROR(I21-H21,"") -> -15007.067
B22: 3 | C22: =IFERROR(IF(B22=B21,C21,""),"") -> 44641 | D22: =IFERROR(MONTH(C22),"") -> 3 | E22: 7 | F22: =IFERROR(VLOOKUP(E22,Bar!$B:$C,2,0),"") -> Chocotorta | G22: 18 | H22: =IFERROR(IFERROR(VLOOKUP(E22,Bar!$B:$D,3,0),"")*G22,"") -> 50710.714 | I22: 4860 | J22: =IFERROR(I22-H22,"") -> -45850.714
B23: 3 | C23: =IFERROR(IF(B23=B22,C22,""),"") -> 44641 | D23: =IFERROR(MONTH(C23),"") -> 3 | E23: 10 | F23: =IFERROR(VLOOKUP(E23,Bar!$B:$C,2,0),"") -> Apple Crumble | G23: 18 | H23: =IFERROR(IFERROR(VLOOKUP(E23,Bar!$B:$D,3,0),"")*G23,"") -> 20118.35 | I23: 4860 | J23: =IFERROR(I23-H23,"") -> -15258.35
B24: 3 | C24: =IFERROR(IF(B24=B23,C23,""),"") -> 44641 | D24: =IFERROR(MONTH(C24),"") -> 3 | E24: 9 | F24: =IFERROR(VLOOKUP(E24,Bar!$B:$C,2,0),"") -> Torta Oreo | G24: 17 | H24: =IFERROR(IFERROR(VLOOKUP(E24,Bar!$B:$D,3,0),"")*G24,"") -> 50759.167 | I24: 4590 | J24: =IFERROR(I24-H24,"") -> -46169.167
B25: 3 | C25: =IFERROR(IF(B25=B24,C24,""),"") -> 44641 | D25: =IFERROR(MONTH(C25),"") -> 3 | E25: 6 | F25: =IFERROR(VLOOKUP(E25,Bar!$B:$C,2,0),"") -> Browrnie Oreo | G25: 18 | H25: =IFERROR(IFERROR(VLOOKUP(E25,Bar!$B:$D,3,0),"")*G25,"") -> 43719.983 | I25: 4860 | J25: =IFERROR(I25-H25,"") -> -38859.983
B26: 3 | C26: =IFERROR(IF(B26=B25,C25,""),"") -> 44641 | D26: =IFERROR(MONTH(C26),"") -> 3 | E26: 11 | F26: =IFERROR(VLOOKUP(E26,Bar!$B:$C,2,0),"") -> Macarrons x12 | G26: 4 | H26: =IFERROR(IFERROR(VLOOKUP(E26,Bar!$B:$D,3,0),"")*G26,"") -> 7673.5 | I26: 2000 | J26: =IFERROR(I26-H26,"") -> -5673.5
B27: 3 | C27: =IFERROR(IF(B27=B23,C23,""),"") -> 44641 | D27: =IFERROR(MONTH(C27),"") -> 3 | E27: 1 | F27: =IFERROR(VLOOKUP(E27,Bar!$B:$C,2,0),"") -> Budín Limón | G27: 4 | H27: =IFERROR(IFERROR(VLOOKUP(E27,Bar!$B:$D,3,0),"")*G27,"") -> 22232.267 | I27: 3200 | J27: =IFERROR(I27-H27,"") -> -19032.267
B28: 3 | C28: =IFERROR(IF(B28=B24,C24,""),"") -> 44641 | D28: =IFERROR(MONTH(C28),"") -> 3 | E28: 2 | F28: =IFERROR(VLOOKUP(E28,Bar!$B:$C,2,0),"") -> Budín zanahoria | G28: 2 | H28: =IFERROR(IFERROR(VLOOKUP(E28,Bar!$B:$D,3,0),"")*G28,"") -> 11116.133 | I28: 1600 | J28: =IFERROR(I28-H28,"") -> -9516.1333
B29: 3 | C29: =IFERROR(IF(B29=B25,C25,""),"") -> 44641 | D29: =IFERROR(MONTH(C29),"") -> 3 | E29: 3 | F29: =IFERROR(VLOOKUP(E29,Bar!$B:$C,2,0),"") -> Budín marmolado | G29: 2 | H29: =IFERROR(IFERROR(VLOOKUP(E29,Bar!$B:$D,3,0),"")*G29,"") -> 11116.133 | I29: 1600 | J29: =IFERROR(I29-H29,"") -> -9516.1333
B30: 3 | C30: =IFERROR(IF(B30=B26,C26,""),"") -> 44641 | D30: =IFERROR(MONTH(C30),"") -> 3 | E30: 4 | F30: =IFERROR(VLOOKUP(E30,Bar!$B:$C,2,0),"") -> Budín frutos secos | G30: 2 | H30: =IFERROR(IFERROR(VLOOKUP(E30,Bar!$B:$D,3,0),"")*G30,"") -> 13209.467 | I30: 1600 | J30: =IFERROR(I30-H30,"") -> -11609.467
B31: 4 | C31: 44645 | D31: =IFERROR(MONTH(C31),"") -> 3 | E31: 7 | F31: =IFERROR(VLOOKUP(E31,Bar!$B:$C,2,0),"") -> Chocotorta | G31: 12 | H31: =IFERROR(IFERROR(VLOOKUP(E31,Bar!$B:$D,3,0),"")*G31,"") -> 33807.143 | I31: 3240 | J31: =IFERROR(I31-H31,"") -> -30567.143
B32: 4 | C32: =IFERROR(IF(B32=B31,C31,""),"") -> 44645 | D32: =IFERROR(MONTH(C32),"") -> 3 | E32: 8 | F32: =IFERROR(VLOOKUP(E32,Bar!$B:$C,2,0),"") -> Cheese Cake Frutos rojos | G32: 12 | H32: =IFERROR(IFERROR(VLOOKUP(E32,Bar!$B:$D,3,0),"")*G32,"") -> 30499.864 | I32: 3240 | J32: =IFERROR(I32-H32,"") -> -27259.864
B33: 4 | C33: =IFERROR(IF(B33=B32,C32,""),"") -> 44645 | D33: =IFERROR(MONTH(C33),"") -> 3 | E33: 6 | F33: =IFERROR(VLOOKUP(E33,Bar!$B:$C,2,0),"") -> Browrnie Oreo | G33: 10 | H33: =IFERROR(IFERROR(VLOOKUP(E33,Bar!$B:$D,3,0),"")*G33,"") -> 24288.88 | I33: 2700 | J33: =IFERROR(I33-H33,"") -> -21588.88
